<?xml version="1.0"?>
<robot xmlns:xacro="http://www.ros.org/wiki/xacro" name="robot">
<xacro:include filename="$(find exproblab_assignment_2)/robot_urdf/urdf/robot_model.gazebo"/>
					
	<xacro:property name="length_wheel" value="0.04" />
	<xacro:property name="radius_wheel" value="0.08" />

	<xacro:macro name="default_inertial" params="mass">
               <inertial>
                       <mass value="${mass}" />
                       <origin rpy="0 1.5707 1.5707" xyz="0 0 0"/>
                       <inertia ixx="0.000526666666667" ixy="0" ixz="0" iyy="0.000526666666667" iyz="0" izz="0.001"/>
               </inertial>
	</xacro:macro>

    <xacro:macro name="wheel_geometry">
		<geometry>
       			<cylinder length="${length_wheel}" radius="${radius_wheel}"/>
     	</geometry>
	</xacro:macro>
	
	
  <material name="black">
    <color rgba="0.0 0.0 0.0 1.0"/>
  </material>
  <material name="blue">
    <color rgba="0.203125 0.23828125 0.28515625 1.0"/>
  </material>
  <material name="green">
    <color rgba="0.0 0.8 0.0 1.0"/>
  </material>
  <material name="grey">
    <color rgba="0.2 0.2 0.2 1.0"/>
  </material>
  <material name="orange">
    <color rgba="1.0 0.423529411765 0.0392156862745 1.0"/>
  </material>
  <material name="brown">
    <color rgba="0.870588235294 0.811764705882 0.764705882353 1.0"/>
  </material>
  <material name="red">
    <color rgba="0.80078125 0.12890625 0.1328125 1.0"/>
  </material>
  <material name="white">
    <color rgba="1.0 1.0 1.0 1.0"/>
  </material>

  <link name="link_chassis">
    <!-- pose and inertial -->
    <pose>0 0 0.1 0 0 0</pose>
    <inertial>
      <mass value="5"/>
      <origin rpy="0 0 0" xyz="0 0 0.1"/>
      <inertia ixx="0.0395416666667" ixy="0" ixz="0" iyy="0.106208333333" iyz="0" izz="0.106208333333"/>
    </inertial>
    <!-- body -->
    <collision name="collision_chassis">
      <geometry>
        <box size="0.5 0.3 0.07"/>
      </geometry>
    </collision>
    <visual>
      <origin rpy="0 0 0" xyz="0 0 0"/>
      <geometry>
        <box size="0.5 0.3 0.07"/>
      </geometry>
      <material name="black"/>
    </visual>
  </link>

  <!-- the four wheels -->
  <link name="link_right_wheel_front">
    <xacro:default_inertial mass="0.5"/>
    <collision name="link_right_wheel_collision">
      <origin rpy="0 1.5707 1.5707" xyz="0 0 0"/>
      <xacro:wheel_geometry />
    </collision>
    <visual name="link_right_wheel_visual">
      <origin rpy="0 1.5707 1.5707" xyz="0 0 0"/>
      <xacro:wheel_geometry />
      <material name="orange"/>
    </visual>
  </link>
  
  <link name="link_right_wheel_back">
    <xacro:default_inertial mass="0.5"/>
    <collision name="link_right_wheel_collision">
      <origin rpy="0 1.5707 1.5707" xyz="0 0 0"/>
      <xacro:wheel_geometry />
    </collision>
    <visual name="link_right_wheel_visual">
      <origin rpy="0 1.5707 1.5707" xyz="0 0 0"/>
      <xacro:wheel_geometry />
      <material name="orange"/>
    </visual>
  </link>

  <link name="link_left_wheel_front">
    <xacro:default_inertial mass="0.5"/>
    <collision name="link_left_wheel_collision">
      <origin rpy="0 1.5707 1.5707" xyz="0 0 0"/>
      <xacro:wheel_geometry />
    </collision>
    <visual name="link_left_wheel_visual">
      <origin rpy="0 1.5707 1.5707" xyz="0 0 0"/>
      <xacro:wheel_geometry />
      <material name="orange"/>
    </visual>
  </link>
  
  <link name="link_left_wheel_back">
    <xacro:default_inertial mass="0.5"/>
    <collision name="link_left_wheel_collision">
      <origin rpy="0 1.5707 1.5707" xyz="0 0 0"/>
      <xacro:wheel_geometry />
    </collision>
    <visual name="link_left_wheel_visual">
      <origin rpy="0 1.5707 1.5707" xyz="0 0 0"/>
      <xacro:wheel_geometry />
      <material name="orange"/>
    </visual>
  </link>

  <!-- the four wheel joints -->
  <joint name="joint_right_wheel_front" type="continuous">
    <origin rpy="0 0 0" xyz="0.15 -0.15 0"/>
    <child link="link_right_wheel_front"/>
    <parent link="link_chassis"/>
    <axis rpy="0 0 0" xyz="0 1 0"/>
    <limit effort="2000" velocity="200"/>
    <joint_properties damping="1.0" friction="1.0"/>
  </joint>
  
  <joint name="joint_right_wheel_back" type="continuous">
    <origin rpy="0 0 0" xyz="-0.15 -0.15 0"/>
    <child link="link_right_wheel_back"/>
    <parent link="link_chassis"/>
    <axis rpy="0 0 0" xyz="0 1 0"/>
    <limit effort="2000" velocity="200"/>
    <joint_properties damping="1.0" friction="1.0"/>
  </joint>
  
  
  <joint name="joint_left_wheel_front" type="continuous">
    <origin rpy="0 0 0" xyz="0.15 0.15 0"/>
    <child link="link_left_wheel_front"/>
    <parent link="link_chassis"/>
    <axis rpy="0 0 0" xyz="0 1 0"/>
    <limit effort="2000" velocity="200"/>
    <joint_properties damping="1.0" friction="1.0"/>
  </joint>
  
  <joint name="joint_left_wheel_back" type="continuous">
    <origin rpy="0 0 0" xyz="-0.15 0.15 0"/>
    <child link="link_left_wheel_back"/>
    <parent link="link_chassis"/>
    <axis rpy="0 0 0" xyz="0 1 0"/>
    <limit effort="2000" velocity="200"/>
    <joint_properties damping="1.0" friction="1.0"/>
  </joint>
  
  <!-- Manipulator for the camera -->

  <!-- Manipulator base -->
  <link name="manipulator_base_link">
  	<inertial>
  		<mass value="0.1"/>
  		<origin xyz="0 0 0" rpy="0 0 0" />
  		<inertia ixx="0.0000416666667" ixy="0" ixz="0" iyy="0.0000416666667" iyz="0" izz="0.0000416666667"/>
  	</inertial>
  	<collision>
  	  <origin xyz="0 0 0" rpy="0 0 0"/>
      <geometry>
        <box size="0.15 0.15 0.1"/>
      </geometry>
  	</collision>
  	<visual>
  	  <origin xyz="0 0 0" rpy="0 0 0"/>
      <geometry>
        <box size="0.15 0.15 0.1"/>
      </geometry>
      <material name="red" />
  	</visual>
  </link>

  <joint name="manipulator_base_joint" type="revolute">
	    <axis xyz="0 0 1"/>
  	  <origin rpy="0 0 0" xyz="0 0 0.08"/>
      <limit effort="1000.0" lower="0" upper="6.28" velocity="1"/>
    <joint_properties damping="1.0" friction="1.0"/>
	    <parent link="link_chassis"/>
  	  <child link="manipulator_base_link"/>
	</joint>

  <!-- Manipulator first joint -->
  <link name="manipulator_link_1">
  	<inertial>
  		<mass value="0.025"/>
  		<origin xyz="0 0 0.3" rpy="0 0 0" />
  		<inertia ixx="0.000010279" ixy="0" ixz="0" iyy="0.000010279" iyz="0" izz="0.000007225"/>
  	</inertial>
  	<collision>
  	  <origin xyz="0 0 0.3" rpy="0 0 0"/>
      <geometry>
        <box size="0.05 0.05 0.6"/>
      </geometry>
  	</collision>
  	<visual>
  	  <origin xyz="0 0 0.3" rpy="0 0 0"/>
      <geometry>
        <box size="0.05 0.05 0.6"/>
      </geometry>
      <material name="orange" />
  	</visual>
  </link>

  <joint name="manipulator_joint_1" type="prismatic">
  	<axis xyz="0 0 1"/>
  	<limit effort="1000" velocity="0.05" lower="-0.2" upper="0"/>
    <joint_properties damping="1.0" friction="1.0"/>
  	<origin rpy="0 0 0" xyz="0 0 0.045"/>
  	<parent link="manipulator_base_link"/>
  	<child link="manipulator_link_1"/>
  </joint>

  <!-- Hokuyo Laser -->
  <joint name="hokuyo_joint" type="fixed">
    <axis xyz="0 1 0" />
    <origin xyz="0.27 0.0 0.0" rpy="0 0 0"/>
    <parent link="link_chassis"/>
    <child link="hokuyo_link"/>
  </joint>

  <link name="hokuyo_link">
    <collision>
      <origin xyz="0 0 0" rpy="0 0 0"/>
      <geometry>
      <box size="0.1 0.05 0.05"/>
      </geometry>
    </collision>

	    <visual>
	      <origin xyz="0 0 0" rpy="0 0 0"/>
	      <geometry>
		<box size="0.1 0.05 0.05"/>
	      </geometry>
	      <material name="red">
		<color rgba="1 0 0 1"/>
	      </material>
	    </visual>

    <inertial>
      <mass value="1e-5" />
      <origin xyz="0 0 0" rpy="0 0 0"/>
      <inertia ixx="1e-6" ixy="0" ixz="0" iyy="1e-6" iyz="0" izz="1e-6" />
    </inertial>
  </link>

  <!-- Camera -->
  <link name="camera_link">
	    <collision>
	      <origin xyz="0 0 0" rpy="0 0 0"/>
	      <geometry>
		<box size="0.05 0.05 0.05"/>
	      </geometry>
	    </collision>
	    <visual>
	      <origin xyz="0 0 0" rpy="0 0 0"/>
	      <geometry>
		<box size="0.05 0.05 0.05"/>
	      </geometry>
	      <material name="yellow">
		<color rgba="1 1 0 1"/>
	      </material>
	    </visual>
	    <inertial>
	      <mass value="1e-5" />
	      <origin xyz="0 0 0" rpy="0 0 0"/>
	      <inertia ixx="1e-6" ixy="0" ixz="0" iyy="1e-6" iyz="0" izz="1e-6" />
	    </inertial> 
  </link>

  <joint name="camera_joint" type="fixed">
  	<axis xyz="0 0 1"/>
  	<origin xyz="0 0 0.625" rpy="0 0 0"/>
  	<parent link="manipulator_link_1"/>
	  <child link="camera_link"/> 
  </joint>

   <!-- transmissions definition -->

  <transmission name="manipulator_base_joint_trans">
    <type>transmission_interface/SimpleTransmission</type>
    <joint name="manipulator_base_joint">
      <hardwareInterface>hardware_interface/EffortJointInterface</hardwareInterface>
    </joint>
    <actuator name="motor1">
      <hardwareInterface>hardware_interface/EffortJointInterface</hardwareInterface>
      <mechanicalInterface>1</mechanicalInterface>
    </actuator>
  </transmission>

  <transmission name="manipulator_joint_1_trans">
    <type>transmission_interface/SimpleTransmission</type>
    <joint name="manipulator_joint_1">
      <hardwareInterface>hardware_interface/EffortJointInterface</hardwareInterface>
    </joint>
    <actuator name="motor2">
      <hardwareInterface>hardware_interface/EffortJointInterface</hardwareInterface>
      <mechanicalInterface>1</mechanicalInterface>
    </actuator>
  </transmission>

  

</robot>
